Workbook

Sheet SUMMARY
A1: DATE : | F1: Weekly wage w.e.f. 01/03/2023 | L1: =16481.55*12/52 -> 3803.4346 | W1: =V5-U5 -> 0
D2: Council Subs Allowance required | G2: 180.28 | I2: Max Subs allowance | L2: =450*3.5*$B$2 -> 0 | N2: =+N5*2/4.333*4 -> 121.70991
D3: INCOME | Q3: DEDUCTIONS
A4: Emp no | B4: Name | C4: Surname | D4: Basic Wage | E4: Sick Fund 20% x weekly | F4: Holiday Fund 36.08% x weekly | G4: Leave Pay 25% x weekly | H4: Subsistence Allowance | I4: Load Incentive | J4: Load Bonus (Assmang) | K4: Adiitional loads | L4: TOTAL | N4: NBCRFLI Levy 0.4% x monthly | O4: Provident 10% x monthly | P4: Wellness 1% x Monthly | Q4: Sick Fund 20% x weekly | R4: Holiday Fund 36.08% x weekly | S4: Leave Pay 25% x weekly | T4: Subsistence Allowance | U4: Staff account/ Loan Deduction | V4: Staff accoun / Loan Balance | W4: Cash Advance Deduction | X4: Cash Advance Balance | Y4: PAYE | Z4: UIF | AA4: TOTAL | AC4: COMMENTS
A5: THEM002 | B5: Kambinda | C5: Luizi | D5: =+$L$1/45*195 -> 16481.55 | E5: =+$L$1*0.2 -> 760.68692 | F5: =+$L$1*(36.08/100) -> 1372.2792 | G5: =+$L$1*0.25 -> 950.85865 | H5: ='L Kambinda'!$B$16 -> 6435.24 | I5: ='L Kambinda'!$B$15 -> 18270 | J5: ='L Kambinda'!$B$20 -> 2100 | K5: ='L Kambinda'!$B$26 -> 0 | L5: =SUM(D5:J5) -> 46370.615 | N5: =+$L$1*4.333*(0.4/100) -> 65.921129 | O5: =+$L$1*4.333*(0.1) -> 1648.0282 | P5: =+$L$1*4.333*0.01 -> 164.80282 | Q5: =+$L$1*0.2 -> 760.68692 | R5: =+$L$1*(36.08/100) -> 1372.2792 | S5: =+$L$1*0.25 -> 950.85865 | T5: ='L Kambinda'!$B$18 -> 5600 | Z5: 177.12 | AA5: =+L5-N5-O5-P5-Q5-R5-S5-T5-U5-Y5-Z5 -> 35630.918
A6: THEM004 | B6: Ndondi Simon | C6: Ndlala | D6: =+$L$1/45*195 -> 16481.55 | E6: =+$L$1*0.2 -> 760.68692 | F6: =+$L$1*(36.08/100) -> 1372.2792 | G6: =+$L$1*0.25 -> 950.85865 | H6: ='Simon Ndlala'!$B$16 -> 6435.24 | I6: ='Simon Ndlala'!$B$15 -> 18270 | J6: ='Simon Ndlala'!$B$20 -> 2100 | K6: ='Simon Ndlala'!$B$26 -> 600 | L6: =SUM(D6:J6) -> 46370.615 | N6: =+$L$1*4.333*(0.4/100) -> 65.921129 | O6: =+$L$1*4.333*(0.1) -> 1648.0282 | P6: =+$L$1*4.333*0.01 -> 164.80282 | Q6: =+$L$1*0.2 -> 760.68692 | R6: =+$L$1*(36.08/100) -> 1372.2792 | S6: =+$L$1*0.25 -> 950.85865 | T6: ='Simon Ndlala'!$B$18 -> 5600 | U6: 1000 | V6: 1000 | Z6: 177.12 | AA6: =+L6-N6-O6-P6-Q6-R6-S6-T6-U6-Y6-Z6 -> 34630.918
A7: THEM008 | B7: Abongile | C7: Mana | D7: =+$L$1/45*195 -> 16481.55 | E7: =+$L$1*0.2 -> 760.68692 | F7: =+$L$1*(36.08/100) -> 1372.2792 | G7: =+$L$1*0.25 -> 950.85865 | H7: ='Abongile Mana'!$B$16 -> 5975.58 | I7: ='Abongile Mana'!$B$15 -> 15660 | J7: ='Abongile Mana'!$B$20 -> 1950 | K7: ='Abongile Mana'!$B$26 -> 400 | L7: =SUM(D7:J7) -> 43150.955 | N7: =+$L$1*4.333*(0.4/100) -> 65.921129 | O7: =+$L$1*4.333*(0.1) -> 1648.0282 | P7: =+$L$1*4.333*0.01 -> 164.80282 | Q7: =+$L$1*0.2 -> 760.68692 | R7: =+$L$1*(36.08/100) -> 1372.2792 | S7: =+$L$1*0.25 -> 950.85865 | T7: ='Abongile Mana'!$B$18 -> 5600 | Z7: 177.12 | AA7: =+L7-N7-O7-P7-Q7-R7-S7-T7-U7-Y7-Z7 -> 32411.258
A8: THEM011 | B8: Kliffet | C8: Williams | D8: =+$L$1/45*195 -> 16481.55 | E8: =+$L$1*0.2 -> 760.68692 | F8: =+$L$1*(36.08/100) -> 1372.2792 | G8: =+$L$1*0.25 -> 950.85865 | H8: ='Kliffet Williams'!$B$16 -> 5515.92 | I8: ='Kliffet Williams'!$B$15 -> 13050 | J8: ='Kliffet Williams'!$B$20 -> 1800 | K8: ='Kliffet Williams'!$B$26 -> 200 | L8: =SUM(D8:J8) -> 39931.295 | N8: =+$L$1*4.333*(0.4/100) -> 65.921129 | O8: =+$L$1*4.333*(0.1) -> 1648.0282 | P8: =+$L$1*4.333*0.01 -> 164.80282 | Q8: =+$L$1*0.2 -> 760.68692 | R8: =+$L$1*(36.08/100) -> 1372.2792 | S8: =+$L$1*0.25 -> 950.85865 | T8: ='Kliffet Williams'!$B$18 -> 5600 | Z8: 177.12 | AA8: =+L8-N8-O8-P8-Q8-R8-S8-T8-U8-Y8-Z8 -> 29191.598
A9: THEM-021 | B9: Resty | C9: Hollander | D9: =+$L$1/45*195 -> 16481.55 | E9: =+$L$1*0.2 -> 760.68692 | F9: =+$L$1*(36.08/100) -> 1372.2792 | G9: =+$L$1*0.25 -> 950.85865 | H9: ='Resty Hollander'!$B$16 -> 5515.92 | I9: ='Resty Hollander'!$B$15 -> 13050 | J9: ='Resty Hollander'!$B$20 -> 1800 | K9: ='Resty Hollander'!$B$26 -> 200 | L9: =SUM(D9:J9) -> 39931.295 | N9: =+$L$1*4.333*(0.4/100) -> 65.921129 | O9: =+$L$1*4.333*(0.1) -> 1648.0282 | P9: =+$L$1*4.333*0.01 -> 164.80282 | Q9: =+$L$1*0.2 -> 760.68692 | R9: =+$L$1*(36.08/100) -> 1372.2792 | S9: =+$L$1*0.25 -> 950.85865 | T9: ='Resty Hollander'!$B$18 -> 5600 | Z9: 177.12 | AA9: =+L9-N9-O9-P9-Q9-R9-S9-T9-U9-Y9-Z9 -> 29191.598
A10: THEM-026 | B10: kgosiema (roy) | C10: Setlhare | D10: =+$L$1/45*195 -> 16481.55 | E10: =+$L$1*0.2 -> 760.68692 | F10: =+$L$1*(36.08/100) -> 1372.2792 | G10: =+$L$1*0.25 -> 950.85865 | H10: ='Roy Setlhare'!$B$16 -> 5515.92 | I10: ='Roy Setlhare'!$B$15 -> 13050 | J10: ='Roy Setlhare'!$B$20 -> 1800 | K10: ='Roy Setlhare'!$B$26 -> 0 | L10: =SUM(D10:J10) -> 39931.295 | N10: =+$L$1*4.333*(0.4/100) -> 65.921129 | O10: =+$L$1*4.333*(0.1) -> 1648.0282 | P10: =+$L$1*4.333*0.01 -> 164.80282 | Q10: =+$L$1*0.2 -> 760.68692 | R10: =+$L$1*(36.08/100) -> 1372.2792 | S10: =+$L$1*0.25 -> 950.85865 | T10: ='Roy Setlhare'!$B$18 -> 5600 | Z10: 177.12 | AA10: =+L10-N10-O10-P10-Q10-R10-S10-T10-U10-Y10-Z10 -> 29191.598
A11: THEM-027 | B11: Sibusiso arnold | C11: Silomo | D11: =+$L$1/45*195 -> 16481.55 | E11: =+$L$1*0.2 -> 760.68692 | F11: =+$L$1*(36.08/100) -> 1372.2792 | G11: =+$L$1*0.25 -> 950.85865 | H11: ='Subisiso Silomo'!$B$16 -> 6435.24 | I11: ='Subisiso Silomo'!$B$15 -> 18270 | J11: ='Subisiso Silomo'!$B$20 -> 2100 | K11: ='Subisiso Silomo'!$B$26 -> 200 | L11: =SUM(D11:J11) -> 46370.615 | N11: =+$L$1*4.333*(0.4/100) -> 65.921129 | O11: =+$L$1*4.333*(0.1) -> 1648.0282 | P11: =+$L$1*4.333*0.01 -> 164.80282 | Q11: =+$L$1*0.2 -> 760.68692 | R11: =+$L$1*(36.08/100) -> 1372.2792 | S11: =+$L$1*0.25 -> 950.85865 | T11: ='Subisiso Silomo'!$B$18 -> 5600 | Z11: 177.12 | AA11: =+L11-N11-O11-P11-Q11-R11-S11-T11-U11-Y11-Z11 -> 35630.918
A12: THEM028 | B12: Sam | C12: Mahlamba | D12: =+$L$1/45*195 -> 16481.55 | E12: =+$L$1*0.2 -> 760.68692 | F12: =+$L$1*(36.08/100) -> 1372.2792 | G12: =+$L$1*0.25 -> 950.85865 | H12: ='Sam Mahlamba'!$B$16 -> 5975.58 | I12: ='Sam Mahlamba'!$B$15 -> 15660 | J12: ='Sam Mahlamba'!$B$20 -> 1950 | K12: ='Sam Mahlamba'!$B$26 -> 400 | L12: =SUM(D12:J12) -> 43150.955 | N12: =+$L$1*4.333*(0.4/100) -> 65.921129 | O12: =+$L$1*4.333*(0.1) -> 1648.0282 | P12: =+$L$1*4.333*0.01 -> 164.80282 | Q12: =+$L$1*0.2 -> 760.68692 | R12: =+$L$1*(36.08/100) -> 1372.2792 | S12: =+$L$1*0.25 -> 950.85865 | T12: ='Sam Mahlamba'!$B$18 -> 5600 | U12: 1000 | V12: 3500 | Z12: 177.12 | AA12: =+L12-N12-O12-P12-Q12-R12-S12-T12-U12-Y12-Z12 -> 31411.258
A13: THEM031 | B13: Petrus Jacobus | C13: Pretorius | D13: =+$L$1/45*195 -> 16481.55 | E13: =+$L$1*0.2 -> 760.68692 | F13: =+$L$1*(36.08/100) -> 1372.2792 | G13: =+$L$1*0.25 -> 950.85865 | H13: ='Petrus Jacobus pretoruis'!$B$16 -> 5515.92 | I13: ='Petrus Jacobus pretoruis'!$B$15 -> 13050 | J13: ='Petrus Jacobus pretoruis'!$B$20 -> 1800 | K13: ='Petrus Jacobus pretoruis'!$B$26 -> 0 | L13: =SUM(D13:J13) -> 39931.295 | N13: =+$L$1*4.333*(0.4/100) -> 65.921129 | O13: =+$L$1*4.333*(0.1) -> 1648.0282 | P13: =+$L$1*4.333*0.01 -> 164.80282 | Q13: =+$L$1*0.2 -> 760.68692 | R13: =+$L$1*(36.08/100) -> 1372.2792 | S13: =+$L$1*0.25 -> 950.85865 | T13: ='Petrus Jacobus pretoruis'!$B$18 -> 5600 | Z13: 177.12 | AA13: =+L13-N13-O13-P13-Q13-R13-S13-T13-U13-Y13-Z13 -> 29191.598
A14: THEM033 | B14: Andries Moitsemang | C14: Mathe | D14: =+$L$1/45*195 -> 16481.55 | E14: =+$L$1*0.2 -> 760.68692 | F14: =+$L$1*(36.08/100) -> 1372.2792 | G14: =+$L$1*0.25 -> 950.85865 | H14: ='Andries Moitsemang Mathe'!$B$16 -> 5975.58 | I14: ='Andries Moitsemang Mathe'!$B$15 -> 15660 | J14: ='Andries Moitsemang Mathe'!$B$20 -> 1950 | K14: ='Andries Moitsemang Mathe'!$B$26 -> 0 | L14: =SUM(D14:J14) -> 43150.955 | N14: =+$L$1*4.333*(0.4/100) -> 65.921129 | O14: =+$L$1*4.333*(0.1) -> 1648.0282 | P14: =+$L$1*4.333*0.01 -> 164.80282 | Q14: =+$L$1*0.2 -> 760.68692 | R14: =+$L$1*(36.08/100) -> 1372.2792 | S14: =+$L$1*0.25 -> 950.85865 | T14: ='Andries Moitsemang Mathe'!$B$18 -> 5500 | Z14: 177.12 | AA14: =+L14-N14-O14-P14-Q14-R14-S14-T14-U14-Y14-Z14 -> 32511.258
A15: THEM037 | B15: Itemogeng Job | C15: Dimengu | D15: =+$L$1/45*195 -> 16481.55 | E15: =+$L$1*0.2 -> 760.68692 | F15: =+$L$1*(36.08/100) -> 1372.2792 | G15: =+$L$1*0.25 -> 950.85865 | H15: ='Job Dimengu'!$B$16 -> 5515.92 | I15: ='Job Dimengu'!$B$15 -> 13050 | J15: ='Job Dimengu'!$B$20 -> 1800 | K15: ='Job Dimengu'!$B$26 -> 600 | L15: =SUM(D15:J15) -> 39931.295 | N15: =+$L$1*4.333*(0.4/100) -> 65.921129 | O15: =+$L$1*4.333*(0.1) -> 1648.0282 | P15: =+$L$1*4.333*0.01 -> 164.80282 | Q15: =+$L$1*0.2 -> 760.68692 | R15: =+$L$1*(36.08/100) -> 1372.2792 | S15: =+$L$1*0.25 -> 950.85865 | T15: ='Job Dimengu'!$B$18 -> 5600 | Z15: 177.12 | AA15: =+L15-N15-O15-P15-Q15-R15-S15-T15-U15-Y15-Z15 -> 29191.598
A16: THEM043 | B16: Stoffel | C16: Sefadi | D16: =+$L$1/45*195 -> 16481.55 | E16: =+$L$1*0.2 -> 760.68692 | F16: =+$L$1*(36.08/100) -> 1372.2792 | G16: =+$L$1*0.25 -> 950.85865 | H16: ='Stoffel Sefadi'!$B$16 -> 6435.24 | I16: ='Stoffel Sefadi'!$B$15 -> 18270 | J16: ='Stoffel Sefadi'!$B$20 -> 2100 | K16: ='Stoffel Sefadi'!$B$26 -> 0 | L16: =SUM(D16:J16) -> 46370.615 | N16: =+$L$1*4.333*(0.4/100) -> 65.921129 | O16: =+$L$1*4.333*(0.1) -> 1648.0282 | P16: =+$L$1*4.333*0.01 -> 164.80282 | Q16: =+$L$1*0.2 -> 760.68692 | R16: =+$L$1*(36.08/100) -> 1372.2792 | S16: =+$L$1*0.25 -> 950.85865 | T16: ='Stoffel Sefadi'!$B$18 -> 5600 | Z16: 177.12 | AA16: =+L16-N16-O16-P16-Q16-R16-S16-T16-U16-Y16-Z16 -> 35630.918
A17: THEM045 | B17: Samuel | C17: Domingo | D17: =+$L$1/45*195 -> 16481.55 | E17: =+$L$1*0.2 -> 760.68692 | F17: =+$L$1*(36.08/100) -> 1372.2792 | G17: =+$L$1*0.25 -> 950.85865 | H17: ='Samuel Domingo'!$B$16 -> 5975.58 | I17: ='Samuel Domingo'!$B$15 -> 15660 | J17: ='Samuel Domingo'!$B$20 -> 1800 | K17: ='Samuel Domingo'!$B$26 -> 400 | L17: =SUM(D17:J17) -> 43000.955 | N17: =+$L$1*4.333*(0.4/100) -> 65.921129 | O17: =+$L$1*4.333*(0.1) -> 1648.0282 | P17: =+$L$1*4.333*0.01 -> 164.80282 | Q17: =+$L$1*0.2 -> 760.68692 | R17: =+$L$1*(36.08/100) -> 1372.2792 | S17: =+$L$1*0.25 -> 950.85865 | T17: ='Samuel Domingo'!$B$18 -> 4200 | Z17: 177.12 | AA17: =+L17-N17-O17-P17-Q17-R17-S17-T17-U17-Y17-Z17 -> 33661.258
A18: THEM046 | B18: Phikane | C18: Matiwane | D18: =+$L$1/45*195 -> 16481.55 | E18: =+$L$1*0.2 -> 760.68692 | F18: =+$L$1*(36.08/100) -> 1372.2792 | G18: =+$L$1*0.25 -> 950.85865 | H18: ='Phikane Matiwane'!$B$16 -> 5975.58 | I18: ='Phikane Matiwane'!$B$15 -> 15660 | J18: ='Phikane Matiwane'!$B$20 -> 1950 | K18: ='Phikane Matiwane'!$B$26 -> 200 | L18: =SUM(D18:J18) -> 43150.955 | N18: =+$L$1*4.333*(0.4/100) -> 65.921129 | O18: =+$L$1*4.333*(0.1) -> 1648.0282 | P18: =+$L$1*4.333*0.01 -> 164.80282 | Q18: =+$L$1*0.2 -> 760.68692 | R18: =+$L$1*(36.08/100) -> 1372.2792 | S18: =+$L$1*0.25 -> 950.85865 | T18: ='Phikane Matiwane'!$B$18 -> 5600 | Z18: 177.12 | AA18: =+L18-N18-O18-P18-Q18-R18-S18-T18-U18-Y18-Z18 -> 32411.258
A19: THEM047 | B19: Kgololo Joseph | C19: Mocwane | D19: =+$L$1/45*195 -> 16481.55 | E19: =+$L$1*0.2 -> 760.68692 | F19: =+$L$1*(36.08/100) -> 1372.2792 | G19: =+$L$1*0.25 -> 950.85865 | H19: ='JACKSON -Kgololo Joseph Mocwane'!$B$16 -> 5975.58 | I19: ='JACKSON -Kgololo Joseph Mocwane'!$B$15 -> 15660 | J19: ='JACKSON -Kgololo Joseph Mocwane'!$B$20 -> 1950 | K19: ='JACKSON -Kgololo Joseph Mocwane'!$B$26 -> 0 | L19: =SUM(D19:J19) -> 43150.955 | N19: =+$L$1*4.333*(0.4/100) -> 65.921129 | O19: =+$L$1*4.333*(0.1) -> 1648.0282 | P19: =+$L$1*4.333*0.01 -> 164.80282 | Q19: =+$L$1*0.2 -> 760.68692 | R19: =+$L$1*(36.08/100) -> 1372.2792 | S19: =+$L$1*0.25 -> 950.85865 | T19: ='JACKSON -Kgololo Joseph Mocwane'!$B$18 -> 5600 | Z19: 177.12 | AA19: =+L19-N19-O19-P19-Q19-R19-S19-T19-U19-Y19-Z19 -> 32411.258
A20: THEM048 | B20: Randall | C20: Bosch | D20: =+$L$1/45*195 -> 16481.55 | E20: =+$L$1*0.2 -> 760.68692 | F20: =+$L$1*(36.08/100) -> 1372.2792 | G20: =+$L$1*0.25 -> 950.85865 | H20: ='Randall Bosch'!$B$16 -> 5056.26 | I20: ='Randall Bosch'!$B$15 -> 10440 | J20: ='Randall Bosch'!$B$20 -> 1650 | K20: ='Randall Bosch'!$B$26 -> 0 | L20: =SUM(D20:J20) -> 36711.635 | N20: =+$L$1*4.333*(0.4/100) -> 65.921129 | O20: =+$L$1*4.333*(0.1) -> 1648.0282 | P20: =+$L$1*4.333*0.01 -> 164.80282 | Q20: =+$L$1*0.2 -> 760.68692 | R20: =+$L$1*(36.08/100) -> 1372.2792 | S20: =+$L$1*0.25 -> 950.85865 | T20: ='Randall Bosch'!$B$18 -> 5600 | Z20: 177.12 | AA20: =+L20-N20-O20-P20-Q20-R20-S20-T20-U20-Y20-Z20 -> 25971.938
A21: THEM049 | B21: Ruwatira | C21: Tapiwa | D21: =+$L$1/45*195 -> 16481.55 | E21: =+$L$1*0.2 -> 760.68692 | F21: =+$L$1*(36.08/100) -> 1372.2792 | G21: =+$L$1*0.25 -> 950.85865 | H21: ='Papilon Ruwatira Tapiwa'!$B$16 -> 6435.24 | I21: ='Papilon Ruwatira Tapiwa'!$B$15 -> 18270 | J21: ='Papilon Ruwatira Tapiwa'!$B$20 -> 2100 | K21: ='Papilon Ruwatira Tapiwa'!$B$26 -> 0 | L21: =SUM(D21:J21) -> 46370.615 | N21: =+$L$1*4.333*(0.4/100) -> 65.921129 | O21: =+$L$1*4.333*(0.1) -> 1648.0282 | P21: =+$L$1*4.333*0.01 -> 164.80282 | Q21: =+$L$1*0.2 -> 760.68692 | R21: =+$L$1*(36.08/100) -> 1372.2792 | S21: =+$L$1*0.25 -> 950.85865 | T21: ='Papilon Ruwatira Tapiwa'!$B$18 -> 5600 | Z21: 177.12 | AA21: =+L21-N21-O21-P21-Q21-R21-S21-T21-U21-Y21-Z21 -> 35630.918
A22: THEM050 | B22: Samuel | C22: Mmotsi | D22: =+$L$1/45*195 -> 16481.55 | E22: =+$L$1*0.2 -> 760.68692 | F22: =+$L$1*(36.08/100) -> 1372.2792 | G22: =+$L$1*0.25 -> 950.85865 | H22: ='Samuel Mmotsi'!$B$16 -> 5515.92 | I22: ='Samuel Mmotsi'!$B$15 -> 13050 | J22: ='Samuel Mmotsi'!$B$20 -> 1800 | K22: ='Samuel Mmotsi'!$B$26 -> 200 | L22: =SUM(D22:J22) -> 39931.295 | N22: =+$L$1*4.333*(0.4/100) -> 65.921129 | O22: =+$L$1*4.333*(0.1) -> 1648.0282 | P22: =+$L$1*4.333*0.01 -> 164.80282 | Q22: =+$L$1*0.2 -> 760.68692 | R22: =+$L$1*(36.08/100) -> 1372.2792 | S22: =+$L$1*0.25 -> 950.85865 | T22: ='Samuel Mmotsi'!$B$18 -> 5600 | Z22: 177.12 | AA22: =+L22-N22-O22-P22-Q22-R22-S22-T22-U22-Y22-Z22 -> 29191.598
A23: THEM051 | B23: Freek | C23: Boss | D23: =+$L$1/45*195 -> 16481.55 | E23: =+$L$1*0.2 -> 760.68692 | F23: =+$L$1*(36.08/100) -> 1372.2792 | G23: =+$L$1*0.25 -> 950.85865 | H23: ='Freek Boss'!$B$16 -> 5515.92 | I23: ='Freek Boss'!$B$15 -> 13050 | J23: ='Freek Boss'!$B$20 -> 1800 | K23: ='Freek Boss'!$B$26 -> 200 | L23: =SUM(D23:J23) -> 39931.295 | N23: =+$L$1*4.333*(0.4/100) -> 65.921129 | O23: =+$L$1*4.333*(0.1) -> 1648.0282 | P23: =+$L$1*4.333*0.01 -> 164.80282 | Q23: =+$L$1*0.2 -> 760.68692 | R23: =+$L$1*(36.08/100) -> 1372.2792 | S23: =+$L$1*0.25 -> 950.85865 | T23: ='Freek Boss'!$B$18 -> 5600 | Z23: 177.12 | AA23: =+L23-N23-O23-P23-Q23-R23-S23-T23-U23-Y23-Z23 -> 29191.598
A24: THEM054 | B24: Letlhogonolo | C24: Gaebidiwe | D24: =+$L$1/45*195 -> 16481.55 | E24: =+$L$1*0.2 -> 760.68692 | F24: =+$L$1*(36.08/100) -> 1372.2792 | G24: =+$L$1*0.25 -> 950.85865 | H24: =' AUBRY Gaebidiwe'!$B$16 -> 5515.92 | I24: =' AUBRY Gaebidiwe'!$B$15 -> 13050 | J24: =' AUBRY Gaebidiwe'!$B$20 -> 1800 | K24: =' AUBRY Gaebidiwe'!$B$26 -> 400 | L24: =SUM(D24:J24) -> 39931.295 | N24: =+$L$1*4.333*(0.4/100) -> 65.921129 | O24: =+$L$1*4.333*(0.1) -> 1648.0282 | P24: =+$L$1*4.333*0.01 -> 164.80282 | Q24: =+$L$1*0.2 -> 760.68692 | R24: =+$L$1*(36.08/100) -> 1372.2792 | S24: =+$L$1*0.25 -> 950.85865 | T24: =' AUBRY Gaebidiwe'!$B$18 -> 5600 | Z24: 177.12 | AA24: =+L24-N24-O24-P24-Q24-R24-S24-T24-U24-Y24-Z24 -> 29191.598
A25: THEM056 | B25: Pieter | C25: Hendrikcs | D25: =+$L$1/45*195 -> 16481.55 | E25: =+$L$1*0.2 -> 760.68692 | F25: =+$L$1*(36.08/100) -> 1372.2792 | G25: =+$L$1*0.25 -> 950.85865 | H25: ='Pieter Hendrikcs'!$B$16 -> 3217.62 | I25: ='Pieter Hendrikcs'!$B$15 -> 0 | J25: ='Pieter Hendrikcs'!$B$20 -> 0 | K25: ='Pieter Hendrikcs'!$B$26 -> 400 | L25: =SUM(D25:J25) -> 22782.995 | N25: =+$L$1*4.333*(0.4/100) -> 65.921129 | O25: =+$L$1*4.333*(0.1) -> 1648.0282 | P25: =+$L$1*4.333*0.01 -> 164.80282 | Q25: =+$L$1*0.2 -> 760.68692 | R25: =+$L$1*(36.08/100) -> 1372.2792 | S25: =+$L$1*0.25 -> 950.85865 | T25: ='Pieter Hendrikcs'!$B$18 -> 4200 | Z25: 177.12 | AA25: =+L25-N25-O25-P25-Q25-R25-S25-T25-U25-Y25-Z25 -> 13443.298
A26: THEM057 | B26: Miguel | C26: Maseka | D26: =+$L$1/45*195 -> 16481.55 | E26: =+$L$1*0.2 -> 760.68692 | F26: =+$L$1*(36.08/100) -> 1372.2792 | G26: =+$L$1*0.25 -> 950.85865 | H26: ='Miguel Maseka'!$B$16 -> 5975.58 | I26: ='Miguel Maseka'!$B$15 -> 15660 | J26: ='Miguel Maseka'!$B$20 -> 1950 | K26: ='Miguel Maseka'!$B$26 -> 800 | L26: =SUM(D26:J26) -> 43150.955 | N26: =+$L$1*4.333*(0.4/100) -> 65.921129 | O26: =+$L$1*4.333*(0.1) -> 1648.0282 | P26: =+$L$1*4.333*0.01 -> 164.80282 | Q26: =+$L$1*0.2 -> 760.68692 | R26: =+$L$1*(36.08/100) -> 1372.2792 | S26: =+$L$1*0.25 -> 950.85865 | T26: ='Miguel Maseka'!$B$18 -> 5600 | Z26: 177.12 | AA26: =+L26-N26-O26-P26-Q26-R26-S26-T26-U26-Y26-Z26 -> 32411.258
A27: THEM058 | B27: Tshidiso | C27: Sethunya | D27: =+$L$1/45*195 -> 16481.55 | E27: =+$L$1*0.2 -> 760.68692 | F27: =+$L$1*(36.08/100) -> 1372.2792 | G27: =+$L$1*0.25 -> 950.85865 | H27: ='Simon Tshidiso Sethunya'!$B$16 -> 5975.58 | I27: ='Simon Tshidiso Sethunya'!$B$15 -> 15660 | J27: ='Simon Tshidiso Sethunya'!$B$20 -> 1950 | K27: ='Simon Tshidiso Sethunya'!$B$26 -> 400 | L27: =SUM(D27:J27) -> 43150.955 | N27: =+$L$1*4.333*(0.4/100) -> 65.921129 | O27: =+$L$1*4.333*(0.1) -> 1648.0282 | P27: =+$L$1*4.333*0.01 -> 164.80282 | Q27: =+$L$1*0.2 -> 760.68692 | R27: =+$L$1*(36.08/100) -> 1372.2792 | S27: =+$L$1*0.25 -> 950.85865 | T27: ='Simon Tshidiso Sethunya'!$B$18 -> 5600 | Z27: 177.12 | AA27: =+L27-N27-O27-P27-Q27-R27-S27-T27-U27-Y27-Z27 -> 32411.258
A28: THEM060 | B28: Johny | C28: Jacobs | D28: =+$L$1/45*195 -> 16481.55 | E28: =+$L$1*0.2 -> 760.68692 | F28: =+$L$1*(36.08/100) -> 1372.2792 | G28: =+$L$1*0.25 -> 950.85865 | H28: ='Johny Jacobs'!$B$16 -> 5975.58 | I28: ='Johny Jacobs'!$B$15 -> 15660 | J28: ='Johny Jacobs'!$B$20 -> 1950 | K28: ='Johny Jacobs'!$B$26 -> 600 | L28: =SUM(D28:J28) -> 43150.955 | N28: =+$L$1*4.333*(0.4/100) -> 65.921129 | O28: =+$L$1*4.333*(0.1) -> 1648.0282 | P28: =+$L$1*4.333*0.01 -> 164.80282 | Q28: =+$L$1*0.2 -> 760.68692 | R28: =+$L$1*(36.08/100) -> 1372.2792 | S28: =+$L$1*0.25 -> 950.85865 | T28: ='Johny Jacobs'!$B$18 -> 5600 | Z28: 177.12 | AA28: =+L28-N28-O28-P28-Q28-R28-S28-T28-U28-Y28-Z28 -> 32411.258
A29: THEM061 | B29: David | C29: Mohapeloa | D29: =+$L$1/45*195 -> 16481.55 | E29: =+$L$1*0.2 -> 760.68692 | F29: =+$L$1*(36.08/100) -> 1372.2792 | G29: =+$L$1*0.25 -> 950.85865 | H29: ='David Mohapeloa'!$B$16 -> 5975.58 | I29: ='David Mohapeloa'!$B$15 -> 15660 | J29: ='David Mohapeloa'!$B$20 -> 1950 | K29: ='David Mohapeloa'!$B$26 -> 0 | L29: =SUM(D29:J29) -> 43150.955 | N29: =+$L$1*4.333*(0.4/100) -> 65.921129 | O29: =+$L$1*4.333*(0.1) -> 1648.0282 | P29: =+$L$1*4.333*0.01 -> 164.80282 | Q29: =+$L$1*0.2 -> 760.68692 | R29: =+$L$1*(36.08/100) -> 1372.2792 | S29: =+$L$1*0.25 -> 950.85865 | T29: ='David Mohapeloa'!$B$18 -> 5600 | Z29: 177.12 | AA29: =+L29-N29-O29-P29-Q29-R29-S29-T29-U29-Y29-Z29 -> 32411.258
D30: =SUM(D5:D29) -> 412038.75 | E30: =SUM(E5:E29) -> 19017.173 | F30: =SUM(F5:F29) -> 34306.98 | G30: =SUM(G5:G29) -> 23771.466 | H30: =SUM(H5:H29) -> 144333.24 | I30: =SUM(I5:I29) -> 362790 | J30: =SUM(J5:J29) -> 45900 | K30: =SUM(K5:K29) -> 6200 | L30: =SUM(L5:L29) -> 1042157.6 | U30: UPDATED 15.12.2025

Sheet Aviwe Hoza - TRIBAL
A1: Aviwe Hoza THEM059 | F1: EXAMPLE
B3: Hotazel Mines | C3: Lohatla Mines | G3: Hotazel Mines | H3: Lohatla Mines
F4: Basic Salary - 7 Loads | G4: 13574.38 | H4: 16481.58
A5: Basic Salary - 7 loads | B5: =H4 -> 16481.58 | F5: Subsistance | G5: 2835 | H5: =+H29*7 -> 3217.62
A6: Loads per mine (total 7 max) | C6: 7 | F6: Total Income | G6: =SUM(G4:G5) -> 16409.38 | H6: =SUM(H4:H5) -> 19699.2
A7: Subsistence allowance per mine | B7: =+$G$29*B6 -> 0 | C7: =H5 -> 3217.62
F8: 8 Loads | G8: 2900 | H8: 2610
A9: No. of loads (>7 loads) | B9: 0 | C9: 3 | D9: =+C6+C9 -> 10 | F9: Additional Subsistance | G9: 405 | H9: =+H29 -> 459.66
A10: Load bonus (>7 loads) | B10: =+$G$30*B9 -> 0 | C10: =+$H$30*C9 -> 7830 | F10: Gross Income | G10: =+$G$6+G8+G9 -> 19714.38 | H10: =+$H$6+H8+H9 -> 22768.86
A11: Additional Subsistance allowance (>7 loads) | B11: =+$G$29*B9 -> 0 | C11: =+$H$29*C9 -> 1378.98
F12: 9 Loads | G12: 5800 | H12: 5220
F13: Additional Subsistance | G13: 810 | H13: =+H29*2 -> 919.32
F14: Gross Income | G14: =+$G$6+G12+G13 -> 23019.38 | H14: =+$H$6+H12+H13 -> 25838.52
A15: Total Load bonus due (>7 loads) | B15: =+B10+C10 -> 7830
A16: Total Subsistence Allowance | B16: =C11+B11+B7+C7 -> 4596.6 | F16: 10 Loads | G16: 8700 | H16: 7830
F17: Additional Subsistance | G17: 1215 | H17: =+H29*3 -> 1378.98
A18: Subsistance already paid as advance | B18: 3000 | F18: Gross Income | G18: =+$G$6+G16+G17 -> 26324.38 | H18: =+$H$6+H16+H17 -> 28908.18
A20: ASSMANG (Load Bonus) | B20: =SUM(B21:B24) -> 0 | C20: < FORMULA. DON'T CHANGE | F20: 11 Loads | G20: 11600 | H20: 10440
F21: Additional Subsistance | G21: 1620 | H21: =+H29*4 -> 1838.64
F22: Gross Income | G22: =+$G$6+G20+G21 -> 29629.38 | H22: =+$H$6+H20+H21 -> 31977.84
F24: 12 Loads | G24: 14500 | H24: 13050
F25: Additional Subsistance | G25: 2025 | H25: =+H29*5 -> 2298.3
A26: ADDITIONAL LOADS | B26: =SUM(B27:B30) -> 0 | C26: < FORMULA. DON'T CHANGE | F26: Gross Income | G26: =+$G$6+G24+G25 -> 32934.38 | H26: =+$H$6+H24+H25 -> 35047.5
F29: Subsistance / load | G29: 405 | H29: 459.66
F30: Incentive / load | G30: 2900 | H30: 2610

Sheet Ayabulela Mdingi - TRIBAL
A1: Ayabulela Mdingi THEM052 | F1: EXAMPLE
B3: Hotazel Mines | C3: Lohatla Mines | G3: Hotazel Mines | H3: Lohatla Mines
F4: Basic Salary - 7 Loads | G4: 13574.38 | H4: 16481.58
A5: Basic Salary - 7 loads | B5: =H4 -> 16481.58 | F5: Subsistance | G5: 2835 | H5: =+H29*7 -> 3217.62
A6: Loads per mine (total 7 max) | C6: 7 | F6: Total Income | G6: =SUM(G4:G5) -> 16409.38 | H6: =SUM(H4:H5) -> 19699.2
A7: Subsistence allowance per mine | B7: =+$G$29*B6 -> 0 | C7: =H5 -> 3217.62
F8: 8 Loads | G8: 2900 | H8: 2610
A9: No. of loads (>7 loads) | B9: 0 | C9: 1 | D9: =+C6+C9 -> 8 | F9: Additional Subsistance | G9: 405 | H9: =+H29 -> 459.66
A10: Load bonus (>7 loads) | B10: =+$G$30*B9 -> 0 | C10: =+$H$30*C9 -> 2610 | F10: Gross Income | G10: =+$G$6+G8+G9 -> 19714.38 | H10: =+$H$6+H8+H9 -> 22768.86
A11: Additional Subsistance allowance (>7 loads) | B11: =+$G$29*B9 -> 0 | C11: =+$H$29*C9 -> 459.66
F12: 9 Loads | G12: 5800 | H12: 5220
F13: Additional Subsistance | G13: 810 | H13: =+H29*2 -> 919.32
F14: Gross Income | G14: =+$G$6+G12+G13 -> 23019.38 | H14: =+$H$6+H12+H13 -> 25838.52
A15: Total Load bonus due (>7 loads) | B15: =+B10+C10 -> 2610
A16: Total Subsistence Allowance | B16: =C11+B11+B7+C7 -> 3677.28 | F16: 10 Loads | G16: 8700 | H16: 7830
F17: Additional Subsistance | G17: 1215 | H17: =+H29*3 -> 1378.98
A18: Subsistance already paid as advance | B18: 3000 | F18: Gross Income | G18: =+$G$6+G16+G17 -> 26324.38 | H18: =+$H$6+H16+H17 -> 28908.18
A20: ASSMANG (Load Bonus) | B20: =SUM(B21:B24) -> 0 | C20: < FORMULA. DON'T CHANGE | F20: 11 Loads | G20: 11600 | H20: 10440
F21: Additional Subsistance | G21: 1620 | H21: =+H29*4 -> 1838.64
F22: Gross Income | G22: =+$G$6+G20+G21 -> 29629.38 | H22: =+$H$6+H20+H21 -> 31977.84
F24: 12 Loads | G24: 14500 | H24: 13050
F25: Additional Subsistance | G25: 2025 | H25: =+H29*5 -> 2298.3
A26: ADDITIONAL LOADS | B26: =SUM(B27:B30) -> 0 | C26: < FORMULA. DON'T CHANGE | F26: Gross Income | G26: =+$G$6+G24+G25 -> 32934.38 | H26: =+$H$6+H24+H25 -> 35047.5
F29: Subsistance / load | G29: 405 | H29: 459.66
F30: Incentive / load | G30: 2900 | H30: 2610

Sheet Pieter Hendrikcs
A1: P Hendrikcs THEM056 | F1: EXAMPLE
B3: Hotazel Mines | C3: Lohatla Mines | G3: Hotazel Mines | H3: Lohatla Mines
F4: Basic Salary - 7 Loads | G4: 13574.38 | H4: 16481.58
A5: Basic Salary - 7 loads | B5: =+H4 -> 16481.58 | F5: Subsistance | G5: 2835 | H5: =+H29*7 -> 3217.62 | K5: 1 | L5: 7.01 DRIEHOEK PIETER
A6: Loads per mine (total 7 max) | B6: 0 | C6: 7 | F6: Total Income | G6: =SUM(G4:G5) -> 16409.38 | H6: =SUM(H4:H5) -> 19699.2 | K6: 2 | L6: 9.01 GLOSAM PIETER
A7: Subsistence allowance per mine | B7: =+$G$29*B6 -> 0 | C7: =+H5 -> 3217.62 | K7: 3 | L7: 11.01 GLOSAM PIETER
F8: 8 Loads | G8: 2900 | H8: 2610 | K8: 4 | L8: 13.01 GLOSAM PIETER
A9: No. of loads (>7 loads) | B9: 0 | D9: =C6+C9 -> 7 | F9: Additional Subsistance | G9: 405 | H9: =+H29 -> 459.66 | K9: 5 | L9: 17.01 EMNAG PIETER | O9: mokala , assmang , sebilo , tawana - R2200
A10: Load bonus (>7 loads) | B10: =+$G$30*B9 -> 0 | C10: =+$H$30*C9 -> 0 | F10: Gross Income | G10: =+$G$6+G8+G9 -> 19714.38 | H10: =+$H$6+H8+H9 -> 22768.86 | K10: 6 | L10: 18.01 EMNAG PIETER | O10: glosam , driehoek , future , afrimat , boskop-R1900
A11: Additional Subsistance allowance (>7 loads) | B11: =+$G$29*B9 -> 0 | C11: =+$H$29*C9 -> 0 | D11: CHECKED(B) | K11: 7 | L11: 21.01 EMANG PIETER
F12: 9 Loads | G12: 5800 | H12: 5220
F13: Additional Subsistance | G13: 810 | H13: =+H29*2 -> 919.32
F14: Gross Income | G14: =+$G$6+G12+G13 -> 23019.38 | H14: =+$H$6+H12+H13 -> 25838.52 | L14: krynie ekstra nie
A15: Total Load bonus due (>7 loads) | B15: =+B10+C10 -> 0
A16: Total Subsistence Allowance | B16: =+B7+C7+B11+C11 -> 3217.62 | F16: 10 Loads | G16: 8700 | H16: 7830 | L16: KOSGELDE
F17: Additional Subsistance | G17: 1215 | H17: =+H29*3 -> 1378.98 | L17: 05.01 SAFETEC | M17: 500
A18: Subsistance already paid as advance | B18: 4200 | C18: CHECKED(B) | F18: Gross Income | G18: =+$G$6+G16+G17 -> 26324.38 | H18: =+$H$6+H16+H17 -> 28908.18 | L18: 05.01 THEMBIS | M18: 900
L19: 12.01 thembis | M19: 1400
A20: ASSMANG (Load Bonus) | C20: < FORMULA. DON'T CHANGE | F20: 11 Loads | G20: 11600 | H20: 10440 | L20: 19.01 THEMBIS | M20: 1400
F21: Additional Subsistance | G21: 1620 | H21: =+H29*4 -> 1838.64
F22: Gross Income | G22: =+$G$6+G20+G21 -> 29629.38 | H22: =+$H$6+H20+H21 -> 31977.84 | M22: =SUM(M17:M21) -> 4200
F24: 12 Loads | G24: 14500 | H24: 13050 | L24: SAND
F25: Additional Subsistance | G25: 2025 | H25: =+H29*5 -> 2298.3 | K25: 13.01.2026 | L25: 38 | M25: DROEFONTEIN | N25: 38.7 | O25: JYC247EC | P25: PIETER | Q25: RECEIVED | R25: 200
A26: ADDITIONAL LOADS | B26: =SUM(B27:B30) -> 400 | C26: < FORMULA. DON'T CHANGE | F26: Gross Income | G26: =+$G$6+G24+G25 -> 32934.38 | H26: =+$H$6+H24+H25 -> 35047.5 | K26: 20.01.2026 | O26: JYC247EC | P26: PIETER | Q26: A MARAIS (R200) | R26: 200
A27: DROEFONTEIN | B27: 200 | R27: =SUM(R25:R26) -> 400
A28: A MARAIS | B28: 200 | C28: CHECKED(B)
F29: Subsistance / load | G29: 405 | H29: 459.66
F30: Incentive / load | G30: 2900 | H30: 2610

Sheet Randall Bosch
A1: R Bosch THEM048 JRC117EC | F1: EXAMPLE
B3: Hotazel Mines | C3: Lohatla Mines | G3: Hotazel Mines | H3: Lohatla Mines | I3: 1 | J3: 6.01 ASSMANG RANDAL
F4: Basic Salary - 7 Loads | G4: 13574.38 | H4: 16481.58 | I4: 2 | J4: 8.01 ASSMANG RANDAL
A5: Basic Salary - 7 loads | B5: =+H4 -> 16481.58 | F5: Subsistance | G5: 2835 | H5: =+H29*7 -> 3217.62 | I5: 3 | J5: 11.01 ASSMANG RANDAL
A6: Loads per mine (total 7 max) | B6: 0 | C6: 7 | F6: Total Income | G6: =SUM(G4:G5) -> 16409.38 | H6: =SUM(H4:H5) -> 19699.2 | I6: 4 | J6: 14.01 ASSMANG RANDAL
A7: Subsistence allowance per mine | B7: =+$G$29*B6 -> 0 | C7: =+H5 -> 3217.62 | I7: 5 | J7: 16.01 ASSMANG RANDAL
F8: 8 Loads | G8: 2900 | H8: 2610 | I8: 6 | J8: 18.01 ASSMANG RANDAL
A9: No. of loads (>7 loads) | B9: 0 | C9: 4 | D9: =C6+C9 -> 11 | F9: Additional Subsistance | G9: 405 | H9: =+H29 -> 459.66 | I9: 7 | J9: 20.01 ASSMANG RANDAL
A10: Load bonus (>7 loads) | B10: =+$G$30*B9 -> 0 | C10: =+$H$30*C9 -> 10440 | F10: Gross Income | G10: =+$G$6+G8+G9 -> 19714.38 | H10: =+$H$6+H8+H9 -> 22768.86 | I10: 8 | J10: 22.01 ASSMANG RANDAL
A11: Additional Subsistance allowance (>7 loads) | B11: =+$G$29*B9 -> 0 | C11: =+$H$29*C9 -> 1838.64 | I11: 9 | J11: 24.01 ASSMNAG RANDAL | O11: mokala , assmang , sebilo , tawana - R2200
F12: 9 Loads | G12: 5800 | H12: 5220 | I12: 10 | J12: PROJECTION RANDALL | K12: KDJ034 | O12: glosam , driehoek , future , afrimat , boskop-R1900
F13: Additional Subsistance | G13: 810 | H13: =+H29*2 -> 919.32 | I13: 11 | J13: PROJECTION RANDALL | K13: KDJ034
F14: Gross Income | G14: =+$G$6+G12+G13 -> 23019.38 | H14: =+$H$6+H12+H13 -> 25838.52 | J14: =11*150 -> 1650 | K14: EKSTRA
A15: Total Load bonus due (>7 loads) | B15: =+B10+C10 -> 10440
A16: Total Subsistence Allowance | B16: =+B7+C7+B11+C11 -> 5056.26 | F16: 10 Loads | G16: 8700 | H16: 7830 | J16: KOSGELDE
F17: Additional Subsistance | G17: 1215 | H17: =+H29*3 -> 1378.98 | J17: 05.01 SAFETEC | K17: 1400
A18: Subsistance already paid as advance | B18: 5600 | C18: CHECKED(B) | F18: Gross Income | G18: =+$G$6+G16+G17 -> 26324.38 | H18: =+$H$6+H16+H17 -> 28908.18 | J18: 12.01 thembis | K18: 1400
J19: 19.01 THEMBIS | K19: 1400
A20: ASSMANG (Load Bonus) | B20: =D9*150 -> 1650 | C20: < FORMULA. DON'T CHANGE | F20: 11 Loads | G20: 11600 | H20: 10440 | J20: 26.01 SAFETEC | K20: 1400
C21: CHECKED(B) | F21: Additional Subsistance | G21: 1620 | H21: =+H29*4 -> 1838.64 | K21: =SUM(K17:K20) -> 5600
F22: Gross Income | G22: =+$G$6+G20+G21 -> 29629.38 | H22: =+$H$6+H20+H21 -> 31977.84
F24: 12 Loads | G24: 14500 | H24: 13050
F25: Additional Subsistance | G25: 2025 | H25: =+H29*5 -> 2298.3
A26: ADDITIONAL LOADS | B26: =SUM(B27:B30) -> 0 | C26: < FORMULA. DON'T CHANGE | F26: Gross Income | G26: =+$G$6+G24+G25 -> 32934.38 | H26: =+$H$6+H24+H25 -> 35047.5
A27: GLENDORE
A28: DROE FONTEIN
A29: AFRIMAT | F29: Subsistance / load | G29: 405 | H29: 459.66
F30: Incentive / load | G30: 2900 | H30: 2610

Sheet Johny Jacobs
A1: Johny Jacobs THEM060 | F1: EXAMPLE | K1: 1 | L1: 6.01 ASSMANG JOHNNY
K2: 2 | L2: 8.01 ASSMANG JOHNNY
B3: Hotazel Mines | C3: Lohatla Mines | G3: Hotazel Mines | H3: Lohatla Mines | K3: 3 | L3: 10.01 ASSMANG JOHNNY
F4: Basic Salary - 7 Loads | G4: 13574.38 | H4: 16481.58 | K4: 4 | L4: 13.01 SEBILO JOHNNY
A5: Basic Salary - 7 loads | B5: =+H4 -> 16481.58 | F5: Subsistance | G5: 2835 | H5: =+H29*7 -> 3217.62 | K5: 5 | L5: 15.01 ASSMNAG JOHNNY
A6: Loads per mine (total 7 max) | B6: 0 | C6: 7 | F6: Total Income | G6: =SUM(G4:G5) -> 16409.38 | H6: =SUM(H4:H5) -> 19699.2 | K6: 6 | L6: 17.01 ASSMNAG JOHNNY
A7: Subsistence allowance per mine | B7: =+$G$29*B6 -> 0 | C7: =+H5 -> 3217.62 | K7: 7 | L7: 19.01 ASSMANG JOHNNY
F8: 8 Loads | G8: 2900 | H8: 2610 | K8: 8 | L8: 21.01 ASSMANG JOHNNY
A9: No. of loads (>7 loads) | B9: 0 | C9: 6 | D9: =+C6+C9 -> 13 | F9: Additional Subsistance | G9: 405 | H9: =+H29 -> 459.66 | K9: 9 | L9: 23.01 ASSMANG JOHNNY
A10: Load bonus (>7 loads) | B10: =+$G$30*B9 -> 0 | C10: =+$H$30*C9 -> 15660 | F10: Gross Income | G10: =+$G$6+G8+G9 -> 19714.38 | H10: =+$H$6+H8+H9 -> 22768.86 | K10: 10 | L10: 25.01 ASSMANG JOHNNY
A11: Additional Subsistance allowance (>7 loads) | B11: =+$G$29*B9 -> 0 | C11: =+$H$29*C9 -> 2757.96 | K11: 11 | L11: 27.01 ASSMANG JOHNNY | O11: mokala , assmang , sebilo , tawana - R2200
F12: 9 Loads | G12: 5800 | H12: 5220 | K12: 12 | L12: PROJECTION | O12: glosam , driehoek , future , afrimat , boskop-R1900
F13: Additional Subsistance | G13: 810 | H13: =+H29*2 -> 919.32 | K13: 13 | L13: PROJECTION
F14: Gross Income | G14: =+$G$6+G12+G13 -> 23019.38 | H14: =+$H$6+H12+H13 -> 25838.52
A15: Total Load bonus due (>7 loads) | B15: =+B10+C10 -> 15660 | L15: =13*150 -> 1950
A16: Total Subsistence Allowance | B16: =B7+C7+B11+C11 -> 5975.58 | F16: 10 Loads | G16: 8700 | H16: 7830
F17: Additional Subsistance | G17: 1215 | H17: =+H29*3 -> 1378.98
A18: Subsistance already paid as advance | B18: 5600 | C18: CHECKED(B) | F18: Gross Income | G18: =+$G$6+G16+G17 -> 26324.38 | H18: =+$H$6+H16+H17 -> 28908.18
A20: ASSMANG (Load Bonus) | B20: =D9*150 -> 1950 | C20: < FORMULA. DON'T CHANGE | F20: 11 Loads | G20: 11600 | H20: 10440 | L20: KOSGELDE
C21: CHECKED(B) | F21: Additional Subsistance | G21: 1620 | H21: =+H29*4 -> 1838.64 | L21: 05.01 SAFETEC | M21: 1400
F22: Gross Income | G22: =+$G$6+G20+G21 -> 29629.38 | H22: =+$H$6+H20+H21 -> 31977.84 | L22: 12.01 thembis | M22: 1400
L23: 19.01 THEMBIS | M23: 1400
F24: 12 Loads | G24: 14500 | H24: 13050 | L24: 26.01 SAFETEC | M24: 1400
F25: Additional Subsistance | G25: 2025 | H25: =+H29*5 -> 2298.3 | M25: =SUM(M21:M24) -> 5600
A26: ADDITIONAL LOADS | B26: =SUM(B27:B30) -> 600 | C26: < FORMULA. DON'T CHANGE | F26: Gross Income | G26: =+$G$6+G24+G25 -> 32934.38 | H26: =+$H$6+H24+H25 -> 35047.5
A27: GLENDORE | L27: SAND
A28: DROE FONTEIN | B28: =200*3 -> 600 | C28: CHECKED(B) | L28: 15.01.2026 | M28: 50 | N28: DROEFONTEIN | O28: 38.28 | P28: JXP813EC | Q28: JOHNNY | R28: RECEIVED | S28: 200
F29: Subsistance / load | G29: 405 | H29: 459.66 | L29: 19.01.2026 | N29: DROEFONTEIN | O29: 39.98 | P29: JXP813EC | Q29: JOHNNY | R29: RECEIVED | S29: 200
F30: Incentive / load | G30: 2900 | H30: 2610 | L30: 21.01.2026 | N30: DROEFONTEIN | O30: 34.86 | P30: JXP813EC | Q30: JOHNNY | R30: RECEIVED | S30: 200
S31: =SUM(S28:S30) -> 600

Sheet Simon Tshidiso Sethunya
A1: Simon Tshidiso Sethunya THEM058 | F1: EXAMPLE | L1: 1 | M1: 6.01 ASSMANG SIMON CASUAL
L2: 2 | M2: 8.01 ASSMANG SIMON CASUAL
B3: Hotazel Mines | C3: Lohatla Mines | G3: Hotazel Mines | H3: Lohatla Mines | L3: 3 | M3: 9.01 ASSMANG SIMON(CASUAL)
F4: Basic Salary - 7 Loads | G4: 13574.38 | H4: 16481.58 | L4: 4 | M4: 11.01 ASSMNAG SIMON(CASUAL
A5: Basic Salary - 7 loads | B5: =+H4 -> 16481.58 | F5: Subsistance | G5: 2835 | H5: =+H29*7 -> 3217.62 | L5: 5 | M5: 14.01 ASSMNAG SIMON(CASUAL)
A6: Loads per mine (total 7 max) | B6: 0 | C6: 7 | F6: Total Income | G6: =SUM(G4:G5) -> 16409.38 | H6: =SUM(H4:H5) -> 19699.2 | L6: 6 | M6: 16.01 ASSMANG SIMON(CASUAL)
A7: Subsistence allowance per mine | B7: =+$G$29*B6 -> 0 | C7: =+H5 -> 3217.62 | L7: 7 | M7: 18.01 ASSMANG SIMON(CASUAL)
F8: 8 Loads | G8: 2900 | H8: 2610 | L8: 8 | M8: 20.01 ASSMNAG SIMON(CASUAL)
A9: No. of loads (>7 loads) | B9: 0 | C9: 6 | D9: =+C6+C9 -> 13 | F9: Additional Subsistance | G9: 405 | H9: =+H29 -> 459.66 | L9: 9 | M9: 21.01 ASSMANG SIMON(CASUAL)
A10: Load bonus (>7 loads) | B10: =+$G$30*B9 -> 0 | C10: =+$H$30*C9 -> 15660 | F10: Gross Income | G10: =+$G$6+G8+G9 -> 19714.38 | H10: =+$H$6+H8+H9 -> 22768.86 | L10: 10 | M10: 23.01 ASSMNAG SIMON(CASUAL)
A11: Additional Subsistance allowance (>7 loads) | B11: =+$G$29*B9 -> 0 | C11: =+$H$29*C9 -> 2757.96 | L11: 11 | M11: 25.01 ASSMANG SIMON(CASUAL) | O11: mokala , assmang , sebilo , tawana - R2200
F12: 9 Loads | G12: 5800 | H12: 5220 | L12: 12 | M12: 27.01 ASSMANG SIMON(CASUAL) | O12: glosam , driehoek , future , afrimat , boskop-R1900
F13: Additional Subsistance | G13: 810 | H13: =+H29*2 -> 919.32 | L13: 13 | M13: projection
F14: Gross Income | G14: =+$G$6+G12+G13 -> 23019.38 | H14: =+$H$6+H12+H13 -> 25838.52 | M14: =13*150 -> 1950
A15: Total Load bonus due (>7 loads) | B15: =+B10+C10 -> 15660
A16: Total Subsistence Allowance | B16: =B7+C7+B11+C11 -> 5975.58 | F16: 10 Loads | G16: 8700 | H16: 7830
F17: Additional Subsistance | G17: 1215 | H17: =+H29*3 -> 1378.98
A18: Subsistance already paid as advance | B18: 5600 | C18: CHECKED(B) | F18: Gross Income | G18: =+$G$6+G16+G17 -> 26324.38 | H18: =+$H$6+H16+H17 -> 28908.18
A20: ASSMANG (Load Bonus) | B20: =D9*150 -> 1950 | C20: < FORMULA. DON'T CHANGE | F20: 11 Loads | G20: 11600 | H20: 10440 | L20: KOSGELDE
C21: CHECKED(B) | F21: Additional Subsistance | G21: 1620 | H21: =+H29*4 -> 1838.64 | L21: 05.01 SAFETEC | M21: 1400
F22: Gross Income | G22: =+$G$6+G20+G21 -> 29629.38 | H22: =+$H$6+H20+H21 -> 31977.84 | L22: 12.01 thembis | M22: 1400
L23: 19.01 THEMBIS | M23: 1400
F24: 12 Loads | G24: 14500 | H24: 13050 | L24: 26.01 SAFETEC | M24: 1400
F25: Additional Subsistance | G25: 2025 | H25: =+H29*5 -> 2298.3 | M25: =SUM(M21:M24) -> 5600
A26: ADDITIONAL LOADS | B26: =SUM(B27:B30) -> 400 | C26: < FORMULA. DON'T CHANGE | F26: Gross Income | G26: =+$G$6+G24+G25 -> 32934.38 | H26: =+$H$6+H24+H25 -> 35047.5
A27: GLENDORE | L27: SAND
A28: DROE FONTEIN | B28: =200*2 -> 400 | C28: CHECKED(B) | L28: 21.01.2026 | N28: DROEFONTEIN | O28: 33.46 | P28: JXP816EC | Q28: SIMON NEW | R28: RECEIVED | S28: 200
F29: Subsistance / load | G29: 405 | H29: 459.66 | L29: 23.01.2026 | N29: DROEFONTEIN | O29: 35.44 | P29: JXP816EC | Q29: SIMON NEW | R29: RECEIVED | S29: 200
F30: Incentive / load | G30: 2900 | H30: 2610 | S30: =SUM(S28:S29) -> 400

Sheet Freek Boss
A1: Freek Boss THEM051 | F1: EXAMPLE | I1: 1 | J1: 5.01 ASSMANG FREEK
I2: 2 | J2: 7.01 ASSMANG FREEK
B3: Hotazel Mines | C3: Lohatla Mines | G3: Hotazel Mines | H3: Lohatla Mines | I3: 3 | J3: 9.01 ASSMANG FREEK
F4: Basic Salary - 7 Loads | G4: 13574.38 | H4: 16481.55 | I4: 4 | J4: 11.01 ASSMNAG FREEK
A5: Basic Salary - 7 loads | B5: =+H4 -> 16481.55 | F5: Subsistance | G5: 2835 | H5: =+H29*7 -> 3217.62 | I5: 5 | J5: 14.01 ASSMNAG FREEK
A6: Loads per mine (total 7 max) | C6: 7 | F6: Total Income | G6: =SUM(G4:G5) -> 16409.38 | H6: =SUM(H4:H5) -> 19699.17 | I6: 6 | J6: 15.01 ASSMANG FREEK
A7: Subsistence allowance per mine | B7: =+$G$29*B6 -> 0 | C7: =+H5 -> 3217.62 | I7: 7 | J7: 18.01 ASSMNAG FREEK
F8: 8 Loads | G8: 2900 | H8: 2610 | I8: 8 | J8: 20.01 ASSMNAG FREEK
A9: No. of loads (>7 loads) | B9: 0 | C9: 5 | D9: =+C6+C9 -> 12 | F9: Additional Subsistance | G9: 405 | H9: =+H29 -> 459.66 | I9: 9 | J9: 22.01 ASSMNAG FREEK
A10: Load bonus (>7 loads) | B10: =+$G$30*B9 -> 0 | C10: =+$H$30*C9 -> 13050 | F10: Gross Income | G10: =+$G$6+G8+G9 -> 19714.38 | H10: =+$H$6+H8+H9 -> 22768.83 | I10: 10 | J10: 24.01 ASSMANG FREEK
A11: Additional Subsistance allowance (>7 loads) | B11: =+$G$29*B9 -> 0 | C11: =+$H$29*C9 -> 2298.3 | I11: 11 | J11: 26.01 ASSMANG FREEK
F12: 9 Loads | G12: 5800 | H12: 5220 | I12: 12 | J12: PROJECTION | M12: mokala , assmang , sebilo , tawana - R2200
F13: Additional Subsistance | G13: 810 | H13: =+H29*2 -> 919.32 | J13: =12*150 -> 1800 | M13: glosam , driehoek , future , afrimat , boskop-R1900
F14: Gross Income | G14: =+$G$6+G12+G13 -> 23019.38 | H14: =+$H$6+H12+H13 -> 25838.49
A15: Total Load bonus due (>7 loads) | B15: =+B10+C10 -> 13050
A16: Total Subsistence Allowance | B16: =B7+C7+B11+C11 -> 5515.92 | F16: 10 Loads | G16: 8700 | H16: 7830 | J16: KOSGELDE
F17: Additional Subsistance | G17: 1215 | H17: =+H29*3 -> 1378.98 | J17: 05.01 THEMBIS | K17: 1400
A18: Subsistance already paid as advance | B18: 5600 | C18: CHECKED(B) | F18: Gross Income | G18: =+$G$6+G16+G17 -> 26324.38 | H18: =+$H$6+H16+H17 -> 28908.15 | J18: 12.01 thembis | K18: 1400
J19: 19.01 THEMBIS | K19: 1400
A20: ASSMANG (Load Bonus) | B20: =D9*150 -> 1800 | C20: < FORMULA. DON'T CHANGE | F20: 11 Loads | G20: 11600 | H20: 10440 | J20: 26.01 SAFETEC | K20: 1400
C21: CHECKED(B) | F21: Additional Subsistance | G21: 1620 | H21: =+H29*4 -> 1838.64 | K21: =SUM(K17:K20) -> 5600
F22: Gross Income | G22: =+$G$6+G20+G21 -> 29629.38 | H22: =+$H$6+H20+H21 -> 31977.81 | J22: SAND
J23: 15.01.2026 | K23: 48 | L23: DROEFONTEIN | M23: 37.76 | N23: JZG083EC | O23: FREEK | P23: RECEIVED | Q23: 200
F24: 12 Loads | G24: 14500 | H24: 13050
F25: Additional Subsistance | G25: 2025 | H25: =+H29*5 -> 2298.3
A26: ADDITIONAL LOADS | B26: =SUM(B27:B30) -> 200 | C26: < FORMULA. DON'T CHANGE | F26: Gross Income | G26: =+$G$6+G24+G25 -> 32934.38 | H26: =+$H$6+H24+H25 -> 35047.47
A27: GLENDORE
A28: DROE FONTEIN | B28: 200 | C28: CHECKED(B)
A29: AFRIMAT | F29: Subsistance / load | G29: 405 | H29: 459.66
F30: Incentive / load | G30: 2900 | H30: 2610

Sheet Resty Hollander
A1: R Hollander THEM021 | F1: EXAMPLE | I1: 1 | J1: 6.01 ASSMANG RETSI
I2: 2 | J2: 8.01 ASSMANG RESTI
B3: Hotazel Mines | C3: Lohatla Mines | G3: Hotazel Mines | H3: Lohatla Mines | I3: 3 | J3: 10.01 ASSMANG RESTI
F4: Basic Salary - 7 Loads | G4: 13574.38 | H4: 16481.55 | I4: 4 | J4: 12.01 ASSMANG RESTI
A5: Basic Salary - 7 loads | B5: =+H4 -> 16481.55 | F5: Subsistance | G5: 2835 | H5: =+H29*7 -> 3217.62 | I5: 5 | J5: 14.01 ASSMNAG RESTI
A6: Loads per mine (total 7 max) | B6: 0 | C6: 7 | F6: Total Income | G6: =SUM(G4:G5) -> 16409.38 | H6: =SUM(H4:H5) -> 19699.17 | I6: 6 | J6: 16.01 ASSMANG RESTI
A7: Subsistence allowance per mine | B7: =+$G$29*B6 -> 0 | C7: =+H5 -> 3217.62 | I7: 7 | J7: 20.01 ASSMNAG RESTI
F8: 8 Loads | G8: 2900 | H8: 2610 | I8: 8 | J8: 22.01 ASSMANG RESTI
A9: No. of loads (>7 loads) | B9: 0 | C9: 5 | D9: =+C6+C9 -> 12 | F9: Additional Subsistance | G9: 405 | H9: =+H29 -> 459.66 | I9: 9 | J9: 24.01 ASSMNAG RESTI
A10: Load bonus (>7 loads) | B10: =+$G$30*B9 -> 0 | C10: =+$H$30*C9 -> 13050 | F10: Gross Income | G10: =+$G$6+G8+G9 -> 19714.38 | H10: =+$H$6+H8+H9 -> 22768.83 | I10: 10 | J10: 26.01 ASSMANG RESTI
A11: Additional Subsistance allowance (>7 loads) | B11: =+$G$29*B9 -> 0 | C11: =+$H$29*C9 -> 2298.3 | I11: 11 | J11: PROJECTION | N11: mokala , assmang , sebilo , tawana - R2200
F12: 9 Loads | G12: 5800 | H12: 5220 | I12: 12 | J12: PROJECTION | N12: glosam , driehoek , future , afrimat , boskop-R1900
F13: Additional Subsistance | G13: 810 | H13: =+H29*2 -> 919.32 | J13: =12*150 -> 1800 | K13: EKSTRA
F14: Gross Income | G14: =+$G$6+G12+G13 -> 23019.38 | H14: =+$H$6+H12+H13 -> 25838.49
A15: Total Load bonus due (>7 loads) | B15: =+B10+C10 -> 13050
A16: Total Subsistence Allowance | B16: =B7+C7+B11+C11 -> 5515.92 | F16: 10 Loads | G16: 8700 | H16: 7830 | J16: KOSGELDE
F17: Additional Subsistance | G17: 1215 | H17: =+H29*3 -> 1378.98 | J17: 05.01 THEMBIS | K17: 1400
A18: Subsistance already paid as advance | B18: 5600 | C18: CHECKED(B) | F18: Gross Income | G18: =+$G$6+G16+G17 -> 26324.38 | H18: =+$H$6+H16+H17 -> 28908.15 | J18: 12.01 thembis | K18: 1400
J19: 19.01 THEMBIS | K19: 1400
A20: ASSMANG (Load Bonus) | B20: =D9*150 -> 1800 | C20: < FORMULA. DON'T CHANGE | F20: 11 Loads | G20: 11600 | H20: 10440 | J20: 26.01 THEMBIS | K20: 1400
C21: CHECKED(B) | F21: Additional Subsistance | G21: 1620 | H21: =+H29*4 -> 1838.64 | K21: =SUM(K17:K20) -> 5600
F22: Gross Income | G22: =+$G$6+G20+G21 -> 29629.38 | H22: =+$H$6+H20+H21 -> 31977.81
J23: SAND
F24: 12 Loads | G24: 14500 | H24: 13050 | J24: 16.01.2026 | L24: DROEFONTEIN | M24: 39.08 | N24: JZS095EC | O24: RESTI | P24: RECEIVED | Q24: 200
F25: Additional Subsistance | G25: 2025 | H25: =+H29*5 -> 2298.3
A26: ADDITIONAL LOADS | B26: =SUM(B27:B30) -> 200 | C26: < FORMULA. DON'T CHANGE | F26: Gross Income | G26: =+$G$6+G24+G25 -> 32934.38 | H26: =+$H$6+H24+H25 -> 35047.47
A27: GLENDORE
A28: DROEFONTEIN | B28: 200 | C28: CHECKED(B)
F29: Subsistance / load | G29: 405 | H29: 459.66
F30: Incentive / load | G30: 2900 | H30: 2610

Sheet Kliffet Williams
A1: K Williams THEM011 | F1: EXAMPLE | I1: 1 | J1: 6.01 ASSMANG KLIFFET
I2: 2 | J2: 8.01 ASSMANG KLIFFET
B3: Hotazel Mines | C3: Lohatla Mines | G3: Hotazel Mines | H3: Lohatla Mines | I3: 3 | J3: 11.01 ASSMNAG KLIFFET
F4: Basic Salary - 7 Loads | G4: 13574.38 | H4: 16481.55 | I4: 4 | J4: 13.01 SEBILO KLIFFET
A5: Basic Salary - 7 loads | B5: =+H4 -> 16481.55 | F5: Subsistance | G5: 2835 | H5: =+H29*7 -> 3217.62 | I5: 5 | J5: 16.01 ASSMANG KLIFFET
A6: Loads per mine (total 7 max) | B6: 0 | C6: 7 | F6: Total Income | G6: =SUM(G4:G5) -> 16409.38 | H6: =SUM(H4:H5) -> 19699.17 | I6: 6 | J6: 18.01 ASSMNAG KLIFFET
A7: Subsistence allowance per mine | B7: =+$G$29*B6 -> 0 | C7: =+H5 -> 3217.62 | I7: 7 | J7: 20.01 ASSMANG KLIFFET
F8: 8 Loads | G8: 2900 | H8: 2610 | I8: 8 | J8: 22.01 ASSMANG KLIFFET
A9: No. of loads (>7 loads) | B9: 0 | C9: 5 | D9: =+C6+C9 -> 12 | F9: Additional Subsistance | G9: 405 | H9: =+H29 -> 459.66 | I9: 9 | J9: 24.01 ASSMANG KLIFFET
A10: Load bonus (>7 loads) | B10: =+$G$30*B9 -> 0 | C10: =+$H$30*C9 -> 13050 | F10: Gross Income | G10: =+$G$6+G8+G9 -> 19714.38 | H10: =+$H$6+H8+H9 -> 22768.83 | I10: 10 | J10: 27.01 ASSMANG KLIFFET
A11: Additional Subsistance allowance (>7 loads) | B11: =+$G$29*B9 -> 0 | C11: =+$H$29*C9 -> 2298.3 | I11: 11 | J11: PROJECTION | O11: mokala , assmang , sebilo , tawana - R2200
F12: 9 Loads | G12: 5800 | H12: 5220 | I12: 12 | J12: PROJECTION | O12: glosam , driehoek , future , afrimat , boskop-R1900
F13: Additional Subsistance | G13: 810 | H13: =+H29*2 -> 919.32 | J13: =12*150 -> 1800
F14: Gross Income | G14: =+$G$6+G12+G13 -> 23019.38 | H14: =+$H$6+H12+H13 -> 25838.49
A15: Total Load bonus due (>7 loads) | B15: =+B10+C10 -> 13050
A16: Total Subsistence Allowance | B16: =C7+B7+B11+C11 -> 5515.92 | F16: 10 Loads | G16: 8700 | H16: 7830 | J16: KOSGELDE
F17: Additional Subsistance | G17: 1215 | H17: =+H29*3 -> 1378.98 | J17: 05.01 SAFETEC | K17: 1400
A18: Subsistance already paid as advance | B18: 5600 | C18: CHECKED(B) | F18: Gross Income | G18: =+$G$6+G16+G17 -> 26324.38 | H18: =+$H$6+H16+H17 -> 28908.15 | J18: 12.01 thembis | K18: 1400
J19: 19.01 THEMBIS | K19: 1400
A20: ASSMANG (Load Bonus) | B20: =D9*150 -> 1800 | C20: < FORMULA. DON'T CHANGE | F20: 11 Loads | G20: 11600 | H20: 10440 | J20: 26.01 SAFETEC | K20: 1400
C21: CHECKED(B) | F21: Additional Subsistance | G21: 1620 | H21: =+H29*4 -> 1838.64
F22: Gross Income | G22: =+$G$6+G20+G21 -> 29629.38 | H22: =+$H$6+H20+H21 -> 31977.81 | K22: =SUM(K17:K21) -> 5600
F24: 12 Loads | G24: 14500 | H24: 13050 | J24: SAND
F25: Additional Subsistance | G25: 2025 | H25: =+H29*5 -> 2298.3 | J25: 15.01.2026 | L25: DROEFONTEIN | M25: 38.3 | N25: KBD393EC | O25: KLIFFET | P25: RECEIVED | Q25: 200
A26: ADDITIONAL LOADS | B26: =SUM(B27:B30) -> 200 | C26: < FORMULA. DON'T CHANGE | F26: Gross Income | G26: =+$G$6+G24+G25 -> 32934.38 | H26: =+$H$6+H24+H25 -> 35047.47
A27: GLENDORE
A28: DROE FONTEIN | B28: 200 | C28: CHECKED(B)
F29: Subsistance / load | G29: 405 | H29: 459.66
F30: Incentive / load | G30: 2900 | H30: 2610

Sheet Samuel Domingo
A1: Samuel Domingo THEM045 | F1: EXAMPLE | K1: 1 | L1: 11.01 ASSMNAG SAMUEL
K2: 2 | L2: 13.01 SEBILO SAMUEL
B3: Hotazel Mines | C3: Lohatla Mines | G3: Hotazel Mines | H3: Lohatla Mines | K3: 3 | L3: 14.01 ASSMANG SAMUEL
F4: Basic Salary - 7 Loads | G4: 13574.38 | H4: 16481.58 | K4: 4 | L4: 16.01 ASSMANG SAMUEL
A5: Basic Salary - 7 loads | B5: =+H4 -> 16481.58 | F5: Subsistance | G5: 2835 | H5: =+H29*7 -> 3217.62 | K5: 5 | L5: 17.01 ASSMNAG SAMUEL
A6: Loads per mine (total 7 max) | B6: 0 | C6: 7 | F6: Total Income | G6: =SUM(G4:G5) -> 16409.38 | H6: =SUM(H4:H5) -> 19699.2 | K6: 6 | L6: 20.01 ASSMANG SAMUEL
A7: Subsistence allowance per mine | B7: =+$G$29*B6 -> 0 | C7: =+H5 -> 3217.62 | K7: 7 | L7: 21.01 ASSMNAG SAMUEL
F8: 8 Loads | G8: 2900 | H8: 2610 | K8: 8 | L8: 23.01 ASSMNAG SAMUEL
A9: No. of loads (>7 loads) | B9: 0 | C9: 6 | D9: =+C6+C9 -> 13 | F9: Additional Subsistance | G9: 405 | H9: =+H29 -> 459.66 | K9: 9 | L9: 25.01 ASSMNAG SAMUEL
A10: Load bonus (>7 loads) | B10: =+$G$30*B9 -> 0 | C10: =+$H$30*C9 -> 15660 | F10: Gross Income | G10: =+$G$6+G8+G9 -> 19714.38 | H10: =+$H$6+H8+H9 -> 22768.86 | K10: 10 | L10: 27.01 ASSMNAG SAMUEL | M10: NUWE
A11: Additional Subsistance allowance (>7 loads) | B11: =+$G$29*B9 -> 0 | C11: =+$H$29*C9 -> 2757.96 | K11: 11 | L11: PROJECTION | M11: NUWE | O11: mokala , assmang , sebilo , tawana - R2200
F12: 9 Loads | G12: 5800 | H12: 5220 | K12: 12 | L12: PROJECTION | M12: NUWE | O12: glosam , driehoek , future , afrimat , boskop-R1900
F13: Additional Subsistance | G13: 810 | H13: =+H29*2 -> 919.32 | K13: 13 | L13: TRUCK COLLECTION - KRY 1 VRAG AS PER JOHAN | M13: NUWE
F14: Gross Income | G14: =+$G$6+G12+G13 -> 23019.38 | H14: =+$H$6+H12+H13 -> 25838.52
A15: Total Load bonus due (>7 loads) | B15: =+B10+C10 -> 15660
A16: Total Subsistence Allowance | B16: =B7+C7+B11+C11 -> 5975.58 | F16: 10 Loads | G16: 8700 | H16: 7830 | L16: =13*150 -> 1950
F17: Additional Subsistance | G17: 1215 | H17: =+H29*3 -> 1378.98 | K17: - | L17: 150(KRYNI EKSTRA VIR TOE DIE LORRIE GAAN HAAL IS NIE )
A18: Subsistance already paid as advance | B18: 4200 | C18: CHECKED(B) | F18: Gross Income | G18: =+$G$6+G16+G17 -> 26324.38 | H18: =+$H$6+H16+H17 -> 28908.18 | L18: =12*150 -> 1800 | M18: EKSTRA
A20: ASSMANG (Load Bonus) | B20: =(D9*150)-150 -> 1800 | C20: < FORMULA. DON'T CHANGE | F20: 11 Loads | G20: 11600 | H20: 10440 | L20: KOSGELDE
C21: CHECKED(B) | F21: Additional Subsistance | G21: 1620 | H21: =+H29*4 -> 1838.64 | L21: 12.01 thembis | M21: 1400
F22: Gross Income | G22: =+$G$6+G20+G21 -> 29629.38 | H22: =+$H$6+H20+H21 -> 31977.84 | L22: 19.01 THEMBIS | M22: 1400
L23: 26.01 SAFETEC | M23: 1400
F24: 12 Loads | G24: 14500 | H24: 13050 | M24: =SUM(M21:M23) -> 4200
F25: Additional Subsistance | G25: 2025 | H25: =+H29*5 -> 2298.3
A26: ADDITIONAL LOADS | B26: =SUM(B27:B30) -> 400 | C26: < FORMULA. DON'T CHANGE | F26: Gross Income | G26: =+$G$6+G24+G25 -> 32934.38 | H26: =+$H$6+H24+H25 -> 35047.5 | L26: SAND
A27: GLENDORE | L27: 14.01.2026 | M27: 44 | N27: DROEFONTEIN | O27: 39.78 | P27: KDJ034EC | Q27: SAMUEL | R27: RECEIVED | S27: 200
A28: DROE FONTEIN | B28: =200*2 -> 400 | C28: CHECKED(B) | L28: 21.01.2026 | N28: DROEFONTEIN | O28: 38.26 | P28: KDJ034EC | Q28: SAMUEL | R28: RECEIVED | S28: 200
F29: Subsistance / load | G29: 405 | H29: 459.66 | S29: =SUM(S27:S28) -> 400
F30: Incentive / load | G30: 2900 | H30: 2610

Sheet David Mohapeloa
A1: David Mohapeloa THEM061 | F1: EXAMPLE | K1: 1 | L1: 7.01 ASSMANG DAVID (CASUAL)
K2: 2 | L2: 8.01 ASSMANG DAVID(CASUAL)
B3: Hotazel Mines | C3: Lohatla Mines | G3: Hotazel Mines | H3: Lohatla Mines | K3: 3 | L3: 10.01 ASSMANG DAVID(CASUAL)
F4: Basic Salary - 7 Loads | G4: 13574.38 | H4: 16481.58 | K4: 4 | L4: 12.01 ASSMANG DAVID(CASUAL)
A5: Basic Salary - 7 loads | B5: =+H4 -> 16481.58 | F5: Subsistance | G5: 2835 | H5: =+H29*7 -> 3217.62 | K5: 5 | L5: 14.01 ASSMANG DAVID(CASUAL)
A6: Loads per mine (total 7 max) | B6: 0 | C6: 7 | F6: Total Income | G6: =SUM(G4:G5) -> 16409.38 | H6: =SUM(H4:H5) -> 19699.2 | K6: 6 | L6: 16.01 ASSMNAG DAVID(CASUAL)
A7: Subsistence allowance per mine | B7: =+$G$29*B6 -> 0 | C7: =+H5 -> 3217.62 | K7: 7 | L7: 18.01 ASSMANG DAVID(CASUAL)
F8: 8 Loads | G8: 2900 | H8: 2610 | K8: 8 | L8: 20.01 ASSMNANG DAVID(CASUAL)
A9: No. of loads (>7 loads) | B9: 0 | C9: 6 | D9: =+C6+C9 -> 13 | F9: Additional Subsistance | G9: 405 | H9: =+H29 -> 459.66 | K9: 9 | L9: 22.01 ASSMANG DAVID(CASUAL)
A10: Load bonus (>7 loads) | B10: =+$G$30*B9 -> 0 | C10: =+$H$30*C9 -> 15660 | F10: Gross Income | G10: =+$G$6+G8+G9 -> 19714.38 | H10: =+$H$6+H8+H9 -> 22768.86 | K10: 10 | L10: 24.01 ASSMANG DAVID(CASUAL)
A11: Additional Subsistance allowance (>7 loads) | B11: =+$G$29*B9 -> 0 | C11: =+$H$29*C9 -> 2757.96 | K11: 11 | L11: 26.01 ASSMANG DAVID(CASUAL) | O11: mokala , assmang , sebilo , tawana - R2200
F12: 9 Loads | G12: 5800 | H12: 5220 | K12: 12 | L12: PROJECTION | O12: glosam , driehoek , future , afrimat , boskop-R1900
F13: Additional Subsistance | G13: 810 | H13: =+H29*2 -> 919.32 | K13: 13 | L13: PROJECTION
F14: Gross Income | G14: =+$G$6+G12+G13 -> 23019.38 | H14: =+$H$6+H12+H13 -> 25838.52
A15: Total Load bonus due (>7 loads) | B15: =+B10+C10 -> 15660
A16: Total Subsistence Allowance | B16: =B7+C7+B11+C11 -> 5975.58 | F16: 10 Loads | G16: 8700 | H16: 7830 | L16: =13*150 -> 1950
F17: Additional Subsistance | G17: 1215 | H17: =+H29*3 -> 1378.98
A18: Subsistance already paid as advance | B18: 5600 | C18: CHECKED(B) | F18: Gross Income | G18: =+$G$6+G16+G17 -> 26324.38 | H18: =+$H$6+H16+H17 -> 28908.18
A20: ASSMANG (Load Bonus) | B20: =D9*150 -> 1950 | C20: < FORMULA. DON'T CHANGE | F20: 11 Loads | G20: 11600 | H20: 10440
C21: CHECKED(B) | F21: Additional Subsistance | G21: 1620 | H21: =+H29*4 -> 1838.64 | N21: DAVID
F22: Gross Income | G22: =+$G$6+G20+G21 -> 29629.38 | H22: =+$H$6+H20+H21 -> 31977.84
L23: 05.01.2026 | M23: SAFETEC | N23: 1400 | O23: KDZ484EC
F24: 12 Loads | G24: 14500 | H24: 13050 | L24: 12.01.2026 | M24: thembis | N24: 1400 | O24: KDZ484EC
F25: Additional Subsistance | G25: 2025 | H25: =+H29*5 -> 2298.3 | L25: 19.01.2026 | M25: thembis | N25: 1400 | O25: KDZ484EC
A26: ADDITIONAL LOADS | B26: =SUM(B27:B30) -> 0 | C26: < FORMULA. DON'T CHANGE | F26: Gross Income | G26: =+$G$6+G24+G25 -> 32934.38 | H26: =+$H$6+H24+H25 -> 35047.5 | L26: 26.01.2026 | M26: SAFETEC | N26: 1400 | O26: KDZ484EC
A27: GLENDORE
A28: DROE FONTEIN | N28: =SUM(N23:N27) -> 5600
F29: Subsistance / load | G29: 405 | H29: 459.66
F30: Incentive / load | G30: 2900 | H30: 2610

Sheet Phikane Matiwane
A1: P Matiwane THEM046 | F1: EXAMPLE | I1: 1 | J1: 6.01 ASSMANG PHIKANE
I2: 2 | J2: 7.01 ASSMANG PHIKANE
B3: Hotazel Mines | C3: Lohatla Mines | G3: Hotazel Mines | H3: Lohatla Mines | I3: 3 | J3: 9.01 ASSMANG PHIKANE
F4: Basic Salary - 7 Loads | G4: 13574.38 | H4: 16481.51 | I4: 4 | J4: 11.01 ASSMNAG PHIKANE
A5: Basic Salary - 7 loads | B5: =+H4 -> 16481.51 | F5: Subsistance | G5: 2835 | H5: =+H29*7 -> 3217.62 | I5: 5 | J5: 13.01 SEBILO PHIKANE
A6: Loads per mine (total 7 max) | B6: 0 | C6: 7 | F6: Total Income | G6: =SUM(G4:G5) -> 16409.38 | H6: =SUM(H4:H5) -> 19699.13 | I6: 6 | J6: 15.01 ASSMNAG PHIKANE
A7: Subsistence allowance per mine | B7: =+$G$29*B6 -> 0 | C7: =+H5 -> 3217.62 | I7: 7 | J7: 17.01 ASSMANG PHIKANE
F8: 8 Loads | G8: 2900 | H8: 2610 | I8: 8 | J8: 19.01 ASSMNAG PHIKANE
A9: No. of loads (>7 loads) | B9: 0 | C9: 6 | D9: =+C6+C9 -> 13 | F9: Additional Subsistance | G9: 405 | H9: =+H29 -> 459.66 | I9: 9 | J9: 21.01 ASSMNAG PHIKANE | O9: mokala , assmang , sebilo , tawana - R2200
A10: Load bonus (>7 loads) | B10: =+$G$30*B9 -> 0 | C10: =+$H$30*C9 -> 15660 | F10: Gross Income | G10: =+$G$6+G8+G9 -> 19714.38 | H10: =+$H$6+H8+H9 -> 22768.79 | I10: 10 | J10: 23.01 ASSMNAG PHIKANE | O10: glosam , driehoek , future , afrimat , boskop-R1900
A11: Additional Subsistance allowance (>7 loads) | B11: =+$G$29*B9 -> 0 | C11: =+$H$29*C9 -> 2757.96 | I11: 11 | J11: 25.01 ASSMANG PHIKANE
F12: 9 Loads | G12: 5800 | H12: 5220 | I12: 12 | J12: 27.01 ASSMANG PHIKANE
F13: Additional Subsistance | G13: 810 | H13: =+H29*2 -> 919.32 | I13: 13 | J13: PROJECTION
F14: Gross Income | G14: =+$G$6+G12+G13 -> 23019.38 | H14: =+$H$6+H12+H13 -> 25838.45 | J14: =13*150 -> 1950
A15: Total Load bonus due (>7 loads) | B15: =+B10+C10 -> 15660
A16: Total Subsistence Allowance | B16: =B7+C7+B11+C11 -> 5975.58 | F16: 10 Loads | G16: 8700 | H16: 7830
F17: Additional Subsistance | G17: 1215 | H17: =+H29*3 -> 1378.98
A18: Subsistance already paid as advance | B18: 5600 | C18: CHECKED(B) | F18: Gross Income | G18: =+$G$6+G16+G17 -> 26324.38 | H18: =+$H$6+H16+H17 -> 28908.11 | J18: KOSGELDE
J19: 05.01 SAFETEC | K19: 1400
A20: ASSMANG (Load Bonus) | B20: =D9*150 -> 1950 | C20: < FORMULA. DON'T CHANGE | F20: 11 Loads | G20: 11600 | H20: 10440 | J20: 12.01 thembis | K20: 1400
C21: CHECKED(B) | F21: Additional Subsistance | G21: 1620 | H21: =+H29*4 -> 1838.64 | J21: 19.01 THEMBIS | K21: 1400
F22: Gross Income | G22: =+$G$6+G20+G21 -> 29629.38 | H22: =+$H$6+H20+H21 -> 31977.77 | J22: 26.01 SAFETEC | K22: 1400
K23: =SUM(K19:K22) -> 5600
F24: 12 Loads | G24: 14500 | H24: 13050
F25: Additional Subsistance | G25: 2025 | H25: =+H29*5 -> 2298.3 | J25: SAND
A26: ADDITIONAL LOADS | B26: =B27+B28+B29+B30 -> 200 | C26: < FORMULA. DON'T CHANGE | F26: Gross Income | G26: =+$G$6+G24+G25 -> 32934.38 | H26: =+$H$6+H24+H25 -> 35047.43 | J26: 15.01.2026 | K26: 97 | L26: DROEFONTEIN | M26: 39.22 | N26: KFK772EC | O26: PHIKANI | P26: RECEIVED | Q26: 200
A27: GLENDORE
A28: DROE FONTEIN | B28: 200 | C28: CHECKED(B)
F29: Subsistance / load | G29: 405 | H29: 459.66
F30: Incentive / load | G30: 2900 | H30: 2610

Sheet Miguel Maseka
A1: Miguel Maseka THEM057 | F1: EXAMPLE | K1: 1 | L1: 5.01 ASSMANG MIGUEL
K2: 2 | L2: 7.01 ASSMANG MIGUEL
B3: Hotazel Mines | C3: Lohatla Mines | G3: Hotazel Mines | H3: Lohatla Mines | K3: 3 | L3: 9.01 ASSMANG MIGUEL
F4: Basic Salary - 7 Loads | G4: 13574.38 | H4: 16481.58 | K4: 4 | L4: 11.01 ASSMNAG MIGUEL
A5: Basic Salary - 7 loads | B5: =+H4 -> 16481.58 | F5: Subsistance | G5: 2835 | H5: =+H29*7 -> 3217.62 | K5: 5 | L5: 1 4.01 ASSMANG MIGUEL
A6: Loads per mine (total 7 max) | B6: 0 | C6: 7 | F6: Total Income | G6: =SUM(G4:G5) -> 16409.38 | H6: =SUM(H4:H5) -> 19699.2 | K6: 6 | L6: 15.01 ASSMANG MIGUEL
A7: Subsistence allowance per mine | B7: =+$G$29*B6 -> 0 | C7: =+H5 -> 3217.62 | K7: 7 | L7: 17.01 ASSMNAG MIGUEL
F8: 8 Loads | G8: 2900 | H8: 2610 | K8: 8 | L8: 19.01 ASSMNAG MIGUEL
A9: No. of loads (>7 loads) | B9: 0 | C9: 6 | D9: =+C6+C9 -> 13 | F9: Additional Subsistance | G9: 405 | H9: =+H29 -> 459.66 | K9: 9 | L9: 21.01 ASSMANG MIGUEL
A10: Load bonus (>7 loads) | B10: =+$G$30*B9 -> 0 | C10: =+$H$30*C9 -> 15660 | F10: Gross Income | G10: =+$G$6+G8+G9 -> 19714.38 | H10: =+$H$6+H8+H9 -> 22768.86 | K10: 10 | L10: 23.01 ASSMANG MIGUEL
A11: Additional Subsistance allowance (>7 loads) | B11: =+$G$29*B9 -> 0 | C11: =+$H$29*C9 -> 2757.96 | K11: 11 | L11: 25.01 ASSMANG MIGUEL | O11: mokala , assmang , sebilo , tawana - R2200
F12: 9 Loads | G12: 5800 | H12: 5220 | K12: 12 | L12: PROJECTION | O12: glosam , driehoek , future , afrimat , boskop-R1900
F13: Additional Subsistance | G13: 810 | H13: =+H29*2 -> 919.32 | K13: 13 | L13: PROJECTION
F14: Gross Income | G14: =+$G$6+G12+G13 -> 23019.38 | H14: =+$H$6+H12+H13 -> 25838.52
A15: Total Load bonus due (>7 loads) | B15: =+B10+C10 -> 15660
A16: Total Subsistence Allowance | B16: =B7+C7+B11+C11 -> 5975.58 | F16: 10 Loads | G16: 8700 | H16: 7830 | L16: =13*150 -> 1950
F17: Additional Subsistance | G17: 1215 | H17: =+H29*3 -> 1378.98
A18: Subsistance already paid as advance | B18: 5600 | C18: CHECKED(B) | F18: Gross Income | G18: =+$G$6+G16+G17 -> 26324.38 | H18: =+$H$6+H16+H17 -> 28908.18
A20: ASSMANG (Load Bonus) | B20: =D9*150 -> 1950 | C20: < FORMULA. DON'T CHANGE | F20: 11 Loads | G20: 11600 | H20: 10440 | L20: KOSGELDE
C21: CHECKED(B) | F21: Additional Subsistance | G21: 1620 | H21: =+H29*4 -> 1838.64 | L21: 05.01 SAFETEC | M21: 1400
F22: Gross Income | G22: =+$G$6+G20+G21 -> 29629.38 | H22: =+$H$6+H20+H21 -> 31977.84 | L22: 12.01 thembis | M22: 1400
L23: 19.01 THEMBIS | M23: 1400
F24: 12 Loads | G24: 14500 | H24: 13050 | L24: 26.01 SAFETEC | M24: 1400
F25: Additional Subsistance | G25: 2025 | H25: =+H29*5 -> 2298.3 | M25: =SUM(M21:M24) -> 5600
A26: ADDITIONAL LOADS | B26: =SUM(B27:B30) -> 800 | C26: < FORMULA. DON'T CHANGE | F26: Gross Income | G26: =+$G$6+G24+G25 -> 32934.38 | H26: =+$H$6+H24+H25 -> 35047.5
A27: GLENDORE | L27: SAND
A28: DROE FONTEIN | B28: =200*4 -> 800 | C28: CHECKED(B) | L28: 15.01.2026 | N28: DROEFONTEIN | O28: 38.76 | P28: KFT767EC | Q28: MIGUEL | R28: RECEIVED | S28: 200
F29: Subsistance / load | G29: 405 | H29: 459.66 | L29: 19.01.2026 | N29: DROEFONTEIN | O29: 40.38 | P29: KFT767EC | Q29: MIGUEL | R29: RECEIVED | S29: 200
F30: Incentive / load | G30: 2900 | H30: 2610 | L30: 21.01.2026 | N30: DROEFONTEIN | O30: 33.16 | P30: KFT767EC | Q30: MIGUEL | R30: RECEIVED | S30: 200
L31: 23.01.2026 | N31: DROEFONTEIN | O31: 35.18 | P31: KFT767EC | Q31: MIGUEL | R31: RECEIVED | S31: 200
S32: =SUM(S28:S31) -> 800

Sheet Andries Moitsemang Mathe
A1: ANDRIES MATHE THEM033 | F1: EXAMPLE | I1: 1 | J1: 7.01 ASSMANG ANDRIES
I2: 2 | J2: 9.01 ASSMANG ANDRIES
B3: Hotazel Mines | C3: Lohatla Mines | G3: Hotazel Mines | H3: Lohatla Mines | I3: 3 | J3: 11.01 ASSMNAG ANDRIES
F4: Basic Salary - 7 Loads | G4: 13574.38 | H4: 16481.55 | I4: 4 | J4: 13.01 SEBILO ANDRIES
A5: Basic Salary - 7 loads | B5: =+H4 -> 16481.55 | F5: Subsistance | G5: 2835 | H5: =+H29*7 -> 3217.62 | I5: 5 | J5: 15.01 ASSMANG ANDRIES
A6: Loads per mine (total 7 max) | C6: 7 | F6: Total Income | G6: =SUM(G4:G5) -> 16409.38 | H6: =SUM(H4:H5) -> 19699.17 | I6: 6 | J6: 17.01 ASSMNAG ANDRIES
A7: Subsistence allowance per mine | B7: =+$G$29*B6 -> 0 | C7: =+H5 -> 3217.62 | I7: 7 | J7: 19.01 ASSMAG ANDRIES
F8: 8 Loads | G8: 2900 | H8: 2610 | I8: 8 | J8: 21.01 ASSMNAG ANDRIES
A9: No. of loads (>7 loads) | B9: 0 | C9: 6 | D9: =+C6+C9 -> 13 | F9: Additional Subsistance | G9: 405 | H9: =+H29 -> 459.66 | I9: 9 | J9: 23.01 ASSMNAG ANDRIES
A10: Load bonus (>7 loads) | B10: =+$G$30*B9 -> 0 | C10: =+$H$30*C9 -> 15660 | F10: Gross Income | G10: =+$G$6+G8+G9 -> 19714.38 | H10: =+$H$6+H8+H9 -> 22768.83 | I10: 10 | J10: 25.01 ASSMANG ANDRIES
A11: Additional Subsistance allowance (>7 loads) | B11: =+$G$29*B9 -> 0 | C11: =+$H$29*C9 -> 2757.96 | I11: 11 | J11: 27.01 ASSMANG ANDRIES | N11: mokala , assmang , sebilo , tawana - R2200
F12: 9 Loads | G12: 5800 | H12: 5220 | I12: 12 | J12: PROJECTION | N12: glosam , driehoek , future , afrimat , boskop-R1900
F13: Additional Subsistance | G13: 810 | H13: =+H29*2 -> 919.32 | I13: 13 | J13: PROJECTION
